File: XRD/Task 1/Si1.XRDML
<?xml version="1.0" encoding="UTF-8"?>
<xrdMeasurements xmlns="http://www.xrdml.com/XRDMeasurement/1.3" xmlns:xsi="http://www.w3.org/2001/XMLSchema-instance" xsi:schemaLocation="http://www.xrdml.com/XRDMeasurement/1.3 http://www.xrdml.com/XRDMeasurement/1.3/XRDMeasurement.xsd" status="Completed">
	<comment>
		<entry/>
	</comment>
	<xrdMeasurement measurementType="Scan" status="Completed">
		<usedWavelength intended="K-Alpha 1">
			<kAlpha1 unit="Angstrom">1.540598</kAlpha1>
			<kAlpha2 unit="Angstrom">1.544426</kAlpha2>
			<kBeta unit="Angstrom">1.392250</kBeta>
			<ratioKAlpha2KAlpha1>0.500000</ratioKAlpha2KAlpha1>
		</usedWavelength>
		<incidentBeamPath>
			<radius unit="mm">173.000</radius>
			<xRayTube>
				<tension unit="kV">10</tension>
				<current unit="mA">10</current>
				<anodeMaterial>Cu</anodeMaterial>
			</xRayTube>
			<divergenceSlit xsi:type="fixedDivergenceSlitType">
				<angle unit="deg">1.000</angle>
			</divergenceSlit>
		</incidentBeamPath>
		<diffractedBeamPath>
			<radius unit="mm">173.000</radius>
			<receivingSlit>
				<height unit="mm">0.100</height>
			</receivingSlit>
		</diffractedBeamPath>
		<scan appendNumber="0" mode="Continuous" scanAxis="2Theta-Omega" status="Completed">
			<header>
				<startTimeStamp>2024-04-23T12:37:55</startTimeStamp>
				<author>
					<name>Core2Duo</name>
				</author>
				<source>
					<applicationSoftware version="2.2.1">X'Pert HighScore</applicationSoftware>
				</source>
			</header>
			<dataPoints>
				<positions axis="2Theta" unit="deg">
					<startPosition>20.040</startPosition>
					<endPosition>139.960</endPosition>
				</positions>
				<commonCountingTime unit="seconds">0.500</commonCountingTime>
				<intensities unit="counts">2 4 4 2 8 2 5 4 3 7 6 2 1 5 5 5 7 4 4 3 1 3 9 7 8 4 4 7 6 5 4 9 10 11 5 4 6 7 4 7 6 4 6 10 2 2 8 9 3 8 3 2 7 5 5 3 5 9 5 5 6 8 4 7 4 5 7 5 4 5 4 5 2 4 5 4 9 6 7 10 6 6 2 7 2 7 3 8 4 5 7 8 5 5 12 8 9 8 6 9 7 6 8 5 7 7 9 6 12 3 9 6 11 7 7 11 7 5 5 11 8 7 9 14 9 9 6 4 12 12 9 11 14 9 10 19 13 13 16 14 17 17 13 14 26 26 25 21 17 21 37 27 18 20 31 33 37 28 17 39 25 33 35 27 19 31 26 27 34 34 26 29 29 28 24 21 27 24 15 21 14 10 19 6 7 8 5 3 7 7 9 2 5 7 5 5 9 3 3 7 1 9 6 4 6 10 7 5 7 7 1 4 8 5 7 7 6 3 4 5 5 7 7 4 6 2 5 3 3 5 4 5 9 4 8 6 6 6 3 9 6 2 3 4 3 6 3 4 7 3 4 6 3 0 4 4 2 7 10 6 8 5 2 3 5 7 4 4 8 5 8 3 8 4 5 5 4 7 7 15 7 6 7 5 3 2 7 6 3 1 9 5 3 3 9 10 4 4 7 3 9 4 10 9 8 9 3 7 12 11 10 9 9 14 6 8 6 5 1 5 3 6 5 10 4 6 5 5 6 10 7 10 4 6 5 6 7 3 9 4 7 8 7 7 9 5 10 7 13 10 9 6 14 9 8 12 12 14 6 17 18 15 10 8 6 10 6 14 6 12 7 8 6 7 7 11 12 9 14 13 13 13 16 10 14 13 12 11 16 16 22 12 17 16 18 20 29 34 23 34 26 34 55 39 41 41 69 87 86 106 172 227 257 378 529 663 827 960 1047 954 824 652 440 315 230 165 77 60 46 38 29 23 19 20 12 12 6 9 12 9 10 7 9 11 7 11 8 5 8 10 6 10 7 3 6 4 6 3 6 7 4 1 4 3 2 1 3 7 4 4 5 6 4 4 4 2 4 1 3 2 5 5 3 5 1 5 4 1 6 3 5 6 2 3 1 7 3 7 3 2 8 3 0 2 2 2 6 0 2 7 5 1 5 4 3 2 3 2 2 10 3 5 5 1 4 3 2 4 2 3 4 4 3 2 2 3 9 0 2 3 6 3 1 3 3 4 4 2 2 4 3 4 4 2 4 6 4 6 3 3 3 4 2 4 1 4 3 1 2 2 3 7 2 6 7 7 4 2 1 5 3 3 3 1 3 2 2 3 5 1 2 3 6 4 2 6 6 3 3 2 2 3 3 6 0 2 2 2 2 11 2 1 3 3 5 3 6 3 0 3 5 2 4 1 1 3 7 4 6 5 7 0 3 5 4 2 5 2 1 3 4 2 1 5 6 2 6 5 1 4 1 2 6 2 3 5 2 2 5 4 4 3 1 4 0 0 3 6 3 2 5 1 1 2 1 2 3 3 3 4 3 3 2 3 4 2 6 6 1 1 5 4 1 2 3 2 3 1 5 3 4 4 0 4 4 3 5 5 1 2 2 0 3 3 5 1 3 0 2 1 0 1 1 4 0 2 2 1 5 4 1 4 4 2 1 2 1 1 3 3 3 4 2 1 3 1 2 3 5 8 3 4 2 9 2 7 3 7 3 2 5 7 4 7 1 2 1 1 5 4 5 5 1 7 4 4 5 3 3 4 4 3 2 2 1 6 6 1 3 4 2 6 5 1 8 8 8 4 4 3 6 3 2 4 5 3 5 2 3 5 1 2 5 3 11 2 5 3 2 2 7 1 2 4 4 2 2 1 4 4 2 1 2 1 0 3 6 5 2 3 2 2 1 2 2 3 1 2 4 4 2 0 3 2 3 2 3 3 1 2 1 2 0 1 1 4 1 5 6 3 2 2 3 6 2 4 0 1 4 2 3 2 4 1 2 2 2 1 1 2 2 4 6 3 4 3 4 1 0 3 7 8 5 1 3 2 1 2 2 6 1 1 3 1 7 1 0 3 1 8 1 1 3 3 2 7 1 5 2 3 1 2 1 6 5 2 0 3 3 1 2 0 3 3 3 1 4 3 1 5 3 2 1 1 3 1 3 7 5 4 2 3 4 4 2 5 1 7 6 3 2 3 3 5 0 2 5 3 3 6 4 2 3 5 3 5 1 5 5 4 3 8 1 4 4 4 2 2 2 3 2 6 2 2 2 1 2 1 1 5 5 2 4 3 1 4 0 2 2 4 1 3 3 5 1 2 2 3 2 3 3 2 3 4 3 5 2 4 4 3 2 3 3 1 0 2 2 2 3 2 3 2 3 1 5 5 1 2 2 2 1 4 4 1 3 3 3 5 2 5 3 2 2 2 1 4 1 2 4 5 2 2 3 8 1 2 2 0 2 4 6 0 1 1 2 5 3 1 4 1 0 3 1 2 1 1 6 2 4 5 3 2 5 4 3 2 3 5 1 0 5 5 9 6 2 2 2 3 2 3 2 5 4 5 2 1 2 1 1 4 3 9 1 4 2 2 4 0 3 2 2 4 2 2 6 4 1 1 6 0 3 4 2 2 2 3 2 5 3 5 0 1 3 3 2 2 6 3 2 3 0 3 3 1 2 3 2 7 5 5 2 2 4 3 2 5 4 4 3 1 7 2 4 2 1 5 2 7 2 6 4 4 1 5 4 4 6 6 1 4 4 5 1 5 2 2 4 4 4 5 10 2 6 4 5 6 5 3 3 6 4 4 8 5 3 2 4 3 4 3 6 4 6 4 1 8 8 3 9 3 10 5 8 4 1 3 4 3 2 4 1 10 5 3 5 4 6 3 3 3 4 7 2 2 4 5 6 5 1 5 4 5 3 4 6 4 7 5 5 6 9 7 6 4 4 10 5 5 5 11 8 4 4 2 5 9 10 8 9 3 5 5 14 6 8 12 11 4 12 11 13 8 11 12 12 17 13 10 12 17 14 18 16 21 23 19 32 35 30 42 67 53 77 72 92 144 190 286 373 447 498 598 532 459 393 344 267 275 282 204 126 95 55 35 39 18 23 20 21 13 15 12 13 15 7 12 7 5 6 9 4 14 11 3 10 4 10 7 4 7 6 1 5 12 2 8 1 3 6 0 9 4 7 6 5 5 4 4 8 5 7 7 4 6 6 3 8 5 3 4 3 5 3 4 8 7 0 3 4 5 4 4 2 6 2 3 1 5 4 4 2 3 5 0 1 3 7 7 1 3 9 3 2 5 4 2 4 1 1 4 7 2 2 1 0 3 1 4 2 3 5 4 3 2 2 3 2 4 1 2 4 4 4 4 6 7 6 3 2 4 1 2 1 3 2 3 7 6 7 5 6 4 6 2 4 3 5 2 6 3 2 6 4 5 4 3 0 0 3 2 3 6 4 3 5 4 3 3 5 4 4 4 2 1 2 4 3 2 2 2 2 5 2 7 4 1 4 1 4 3 4 5 6 2 2 2 3 0 3 4 3 1 3 2 3 4 2 4 1 3 4 1 6 2 2 0 3 9 2 4 2 7 5 6 1 6 0 2 4 3 3 5 3 2 3 1 2 0 1 8 3 5 3 2 4 4 3 2 2 7 5 3 5 3 2 3 1 1 1 0 1 4 7 6 0 1 0 3 1 3 2 3 2 3 1 1 5 0 1 0 0 4 4 2 2 3 2 2 4 8 3 1 3 3 1 3 5 5 5 7 5 2 6 6 4 3 1 3 6 6 11 3 5 2 4 7 4 3 3 3 0 4 5 5 3 2 0 4 2 2 2 7 5 4 5 2 3 5 4 2 6 2 4 2 3 6 1 3 2 3 4 4 2 4 3 3 6 5 2 7 5 4 4 1 3 6 6 4 0 3 3 2 3 2 2 3 9 5 8 7 2 5 2 3 5 6 7 1 1 3 7 3 4 2 3 4 3 10 6 12 8 2 11 11 6 6 6 7 10 8 14 7 19 13 14 11 17 13 24 17 26 25 24 40 56 61 76 100 133 179 218 289 310 300 291 241 193 167 155 157 162 141 90 82 57 39 26 18 9 16 15 10 12 12 13 12 6 4 1 8 5 4 8 7 7 3 6 9 2 7 1 5 2 1 2 3 3 3 3 6 6 2 5 2 2 4 1 8 1 4 3 1 2 0 5 4 2 5 0 1 0 5 2 3 4 2 0 0 3 1 2 3 0 4 2 2 6 0 2 2 2 1 2 0 3 2 3 2 2 5 1 3 4 2 4 3 4 2 1 1 2 2 2 2 3 2 1 3 1 4 4 2 3 2 1 3 4 0 4 1 3 4 2 3 1 1 3 4 2 2 0 5 3 1 0 3 3 0 0 3 1 4 2 2 3 2 1 2 1 0 1 2 2 1 4 1 5 4 1 4 3 1 1 3 3 1 1 1 3 2 4 5 1 3 3 1 9 4 3 2 1 2 1 2 2 3 2 1 2 3 1 1 0 1 2 4 0 1 6 0 2 0 1 2 1 1 2 3 5 4 2 1 4 3 4 4 0 1 3 1 1 2 2 0 0 3 3 2 1 4 3 1 5 1 0 3 2 1 3 1 0 2 4 0 1 3 1 2 0 4 4 4 0 2 0 0 3 0 4 2 1 1 2 1 1 1 2 3 2 3 5 4 0 1 5 2 3 2 0 2 0 2 4 1 0 0 1 3 1 1 3 3 2 2 2 4 2 3 3 4 3 2 2 2 4 2 4 2 2 1 0 4 1 1 2 1 1 2 1 1 4 6 3 1 3 3 1 1 1 3 6 0 1 1 1 3 1 4 3 1 2 2 0 4 4 2 2 0 0 2 3 3 3 6 3 2 2 2 2 4 2 2 1 1 3 2 2 1 0 2 1 2 1 2 3 1 2 2 3 2 1 1 1 3 1 2 0 1 4 5 1 1 3 2 1 0 2 0 1 3 4 2 1 3 0 2 2 2 3 2 2 1 3 2 1 0 1 3 2 1 4 4 1 4 2 2 2 3 2 1 4 4 1 2 3 0 2 3 0 1 2 5 1 3 5 3 2 2 0 2 2 3 1 3 2 3 0 1 2 5 3 3 1 3 1 2 4 1 4 2 3 3 4 3 4 1 1 0 3 0 3 1 2 0 3 2 4 3 1 2 1 2 0 2 0 2 0 1 2 2 3 1 2 0 2 0 1 1 1 2 3 2 3 0 1 1 1 4 4 2 2 2 1 2 1 1 1 4 1 2 3 1 3 2 1 0 1 4 1 3 0 1 1 2 2 0 3 1 3 2 0 1 1 1 2 1 4 3 2 1 4 3 2 3 2 1 1 1 2 1 2 4 3 2 4 4 3 1 5 4 1 3 0 2 1 4 2 3 1 3 1 3 5 0 4 2 1 2 2 3 1 3 3 4 1 6 1 0 2 3 2 2 2 2 3 5 3 2 3 2 5 4 7 7 7 6 6 10 5 8 6 6 13 11 10 11 17 19 24 43 33 58 83 67 67 64 45 31 30 38 26 33 42 28 39 31 26 20 13 11 9 5 8 2 4 3 2 4 0 6 2 9 3 3 1 1 5 1 0 2 2 5 2 3 2 3 4 1 1 2 2 1 1 3 4 3 1 1 3 0 2 1 2 1 0 0 0 0 0 2 1 5 2 3 2 2 2 1 3 2 1 4 1 3 6 5 3 3 1 2 5 1 4 1 2 1 1 1 0 1 2 2 1 0 0 2 1 0 2 1 3 1 1 4 3 4 2 6 2 1 1 3 2 2 5 2 2 1 1 1 1 2 5 1 2 3 2 3 1 4 1 2 2 0 0 1 2 2 3 2 4 0 1 2 2 0 0 2 2 3 2 1 1 1 1 3 2 3 1 3 3 4 3 3 0 5 1 2 0 5 0 3 3 0 1 2 3 2 2 2 3 2 1 2 3 2 5 3 2 3 3 2 1 2 1 2 1 2 2 5 0 2 3 2 2 5 2 0 3 1 2 0 2 2 4 3 1 0 1 3 2 2 2 3 3 0 6 1 0 2 1 0 0 2 0 3 2 2 0 1 1 0 7 4 1 1 2 1 3 1 2 1 1 3 2 2 2 2 3 0 2 3 5 2 5 4 2 1 3 1 2 0 0 4 2 3 2 0 4 1 1 1 5 1 2 5 3 3 6 3 3 2 2 1 1 1 4 2 3 3 2 3 1 1 2 4 5 3 4 6 1 0 3 5 6 1 3 4 4 5 3 7 2 1 4 6 3 4 4 4 4 5 2 4 7 5 6 7 7 4 12 9 13 10 10 14 19 16 30 24 33 58 61 78 104 96 128 118 96 76 56 52 61 46 45 58 56 54 42 55 45 34 17 17 11 9 8 9 5 5 9 6 4 3 4 3 1 3 3 1 4 4 6 2 3 1 4 3 3 3 2 0 2 2 4 4 1 2 3 1 3 6 2 1 2 5 3 5 1 2 1 1 5 1 3 4 2 5 4 3 3 2 1 1 5 2 2 2 1 4 2 1 5 1 4 2 2 3 2 1 0 3 2 2 4 2 2 1 2 1 2 1 1 0 2 3 1 4 3 0 3 1 1 1 1 4 1 1 2 1 1 3 2 0 2 4 4 0 0 3 2 1 2 2 4 2 1 2 2 6 2 2 0 1 4 4 4 2 0 0 0 2 1 1 1 1 3 1 6 4 4 0 5 3 2 1 0 0 1 1 4 5 2 3 3 0 3 3 3 4 0 4 2 1 1 4 3 2 0 2 3 1 6 3 2 1 2 2 1 3 5 2 2 1 3 0 0 2 6 1 0 4 4 3 2 4 4 2 3 6 2 4 3 2 1 3 0 2 4 3 5 1 2 0 2 1 0 3 3 2 1 4 2 1 3 3 2 1 6 1 2 1 1 2 1 2 4 2 0 1 0 1 3 0 4 3 3 3 1 2 1 1 3 2 5 0 2 3 0 5 3 4 5 1 3 2 1 0 5 6 3 4 2 2 1 2 0 3 1 5 0 2 1 2 4 2 0 3 2 3 0 2 1 2 2 2 3 3 3 4 1 2 4 1 1 3 5 4 4 2 5 1 1 1 2 3 0 3 2 2 3 2 0 1 1 0 0 2 2 2 5 6 2 4 0 3 3 5 4 2 4 2 3 0 3 2 4 1 2 2 2 1 2 4 3 2 5 2 3 3 1 2 1 1 7 1 1 2 1 0 0 3 2 0 1 1 1 2 1 3 1 5 4 4 6 3 2 1 2 1 1 1 2 1 6 5 4 1 3 4 0 1 3 3 5 2 3 2 3 2 1 2 1 3 4 1 3 4 1 4 1 1 2 1 3 3 0 0 6 4 1 3 2 1 0 3 3 2 5 3 1 1 5 1 1 1 3 6 4 4 3 4 5 1 2 2 4 2 3 5 2 8 7 3 3 3 2 0 2 3 1 3 0 1 3 2 3 1 1 6 3 6 3 4 2 4 5 2 2 4 5 3 6 2 3 3 3 4 2 2 7 1 7 4 1 5 4 3 6 4 1 7 3 6 3 5 3 5 3 4 3 6 2 7 1 5 3 3 7 7 8 6 8 10 13 9 4 6 4 12 10 13 4 6 11 19 19 20 18 17 23 20 27 44 65 98 130 129 146 173 176 165 123 87 60 66 46 42 43 52 66 91 67 78 79 83 66 63 27 20 18 13 8 19 12 8 5 8 5 2 13 5 8 2 6 7 3 2 3 3 6 4 2 7 2 7 4 2 2 2 3 2 2 5 3 3 3 3 4 3 4 2 1 3 2 3 3 2 3 3 2 4 7 1 2 1 3 3 2 1 2 3 7 0 2 3 3 0 1 3 2 4 3 6 3 1 0 1 2 0 3 1 2 3 2 1 4 0 2 3 3 2 4 1 4 3 1 1 1 1 1 3 1 2 3 0 4 1 1 3 0 2 1 5 2 3 1 1 1 3 0 1 2 0 3 4 3 2 2 5 1 4 0 2 2 1 2 2 3 0 1 6 3 3 2 3 1 7 4 1 2 4 0 2 3 1 0 5 0 0 3 4 1 3 5 0 1 2 1 4 3 2 3 1 1 1 1 1 3 3 1 4 1 3 3 3 3 1 0 1 3 1 0 1 0 2 3 4 6 2 0 1 3 2 2 2 2 3 2 2 0 0 3 3 2 3 1 2 3 2 0 0 4 3 2 3 2 2 0 3 1 4 6 2 2 1 3 4 4 1 2 0 2 6 2 0 0 1 4 4 3 5 2 1 2 4 5 3 4 1 3 4 2 1 1 0 0 1 3 3 2 2 2 1 4 3 5 5 5 5 5 1 2 4 4 8 4 4 3 5 3 4 6 6 2 2 3 3 5 5 3 2 6 2 7 5 6 6 5 9 8 12 11 13 17 7 13 20 17 27 37 30 51 74 91 82 104 108 87 67 60 48 40 33 22 20 24 27 29 44 54 44 49 57 35 27 30 16 13 11 11 11 6 8 8 5 6 5 2 4 4 8 2 4 5 9 3 1 4 3 2 1 2 1 7 9 4 1 2 3 0 1 2 0 1 3 2 2 3 1 3 3 2 2 4 2 1 2 2 3 1 2 2 3 2 4 3 2 2 2 2 4 2 0 5 0 3 3 6 0 4 3 1 2 3 4 1 1 5 1 2 2 1 0 2 3 2 3 1 2 3 1 1 0 3 1 3 3 1 1 2 2 0 2 0 5 1 4 2 4 1 0 0 0 3 1 0 5 6 2 1 3 5 3 2 3 1 4 5 0 0 3 1 2 0 1 3 1 1 1 1 1 5 4 3 3 2 2 1 2 2 2 2 2 3 3 2 4 2 4 3 5 3 1 0 3 2 1 1 3 1 2 2 1 5 1 0 3 3 1 1 1 1 2 0 1 1 1 2 1 1 1 3 2 1 3 0 1 2 3 0 2 0 2 0 0 2 2 4 2 0 2 2 1 1 3 1 4 5 3 1 2 0 3 2 2 3 1 4 1 3 4 2 4 4 5 2 4 2 1 0 2 4 2 2 0 3 0 1 0 3 0 1 2 2 2 3 3 0 4 2 1 2 2 1 3 1 0 2 5 0 1 5 3 1 0 3 1 1 2 1 2 1 1 1 1 2 2 0 1 3 1 3 2 3 5 1 0 1 3 4 5 1 0 1 1 3 0 1 1 0 1 3 1 0 0 0 2 0 0 0 2 4 2 4 2 1 1 2 1 1 0 2 2 1 2 3 2 1 4 2 2 0 2 0 0 0 2 1 3 4 2 1 2 0 1 5 5 2 3 2 7 2 3 3 4 2 4 2 1 0 3 1 4 0 2 1 2 2 2 1 0 4 2 0 2 1 2 2 1 2 1 3 0 2 1 1 1 1 1 3 1 2 3 4 1 2 3 1 1 1 3 1 3 2 3 2 1 2 2 1 0 1 2 2 3 3 1 3 2 3 3 4 1 3 4 4 0 2 3 0 0 2 2 1 3 5 3 0 1 2 0 1 2 2 2 1 2 2 0 2 4 3 3 2 3 2 2 2 1 5 2 3 1 1 1 5 1 3 2 4 3 5 2 4 0 1 0 4 1 5 2 2 3 1 2 2 4 2 4 2 7 1 5 5 3 2 2 1 3 2 3 5 2 1 2 3 5 5 3 1 2 3 1 1 7 2 0 6 1 2 4 8 6 1 3 5 8 2 4 3 4 0 7 4 6 4 8 5 7 8 3 4 10 12 15 13 14 20 26 25 40 36 52 54 51 48 54 38 44 27 17 19 13 22 13 13 8 20 22 17 16 30 27 24 21 26 21 15 13 15 7 5 10 5 4 6 5 5 5 3 6 1 4 1 5 0 7 4 1 4 3 3 3 4 2 3 1 7 2 5 0 3 5 2 3 5 3 7 3 4 2 5 2 6 2 3 2 1 6 1 3 3 1 1 0 5 0 2 2 4 4 1 3 1 0 1 1 3 4 3 1 5 1 3 1 2 3 3 2 1 5 1 2 5 3 4 4 2 0 4 1 4 1 2 2 4 3 1 4 3 2 6 3 4 3 2 2 3 2 4 3 3 4 2 4 3 4 1 3 2 0 2 0 3 2 3 1 5 3 1 1 1 6 3 4 2 3 4 2 0 2 3 2 1 4 3 0 5 6 2 4 3 5 2 4 4 6 3 2 3 4 1 2 3 3 2 5 1 3 4 3 2 4 2 2 3 2 3 2 1 1 0 3 2 4 1 2 2 2 3 4 2 1 1 1 2 1 2 2 3 4 2 1 0 4 3 4 2 1 5 1 3 0 2 3 4 1 8 3 4 2 6 0 1 5 4 3 1 4 4 3 5 1 4 2 1 1 2 0 2 3 1 1 2 4 2 3 0 4 6 2 2 1 3 2 2 2 1 2 1 2 1 6 5 6 5 2 1 2 3 0 4 5 3 2 3 6 2 2 4 2 2 5 5 5 2 3 2 5 4 3 2 5 1 4 4 4 1 3 7 4 7 2 5 5 4 4 5 7 4 6 6 10 6 3 3 9 5 2 7 5 8 18 10 5 7 6 12 8 17 20 16 17 14 16 17 32 37 41 49 66 76 93 86 92 109 103 68 57 35 40 36 31 38 14 16 16 22 29 32 22 27 50 52 60 50 58 41 34 35 28 34 23 20 10 19 10 13 8 9 7 4 8 6 7 4 8 1 3 4 1 6 3 0 3 6 5 6 4 4 3 4 4 4 7 9 6 1 2 3 2 3 2 1 4 1 4 6 1 2 2 2 3 0 2 4 1 4 2 1 4 7 1 2 5 2 0 0 4 2 5 3 5 3 2 4 3 2 2 3 1 6 0 9 2 1 1 4 6 1 4 3 2 2 2 2 2 4 4 2 3 0 1 4 2 3 2 0 2 5 4 3 0 2 0 0 1 2 4 3 2 3 4 3 0 3 1 1 1 6 1 2 1 3 1 3 2 2 2 1 4 3 4 3 4 6 3 2 3 3 3 2 1 2 7 3 2 0 1 1 1 5 2 3 2 0 1 3 2 4 4 4 2 3 2 2 1 0 1 1 4 5 1 4 3 2 5 2 4 1 3 2 0 2 3 1 2 1 2 3 2 2 1 3 4 3 1 2 5 2 7 0 5 4 3 1 0 2 0 0 2 3 1 1 1 1 1 3 0 0 0 2 3 1 3 2 3 6 2 3 1 3 0 4 4 4 0 0 4 5 4 4 4 3 1 1 4 4 1 0 4 3 1 0 1 3 4 4 1 1 2 1 1 3 3 1 2 3 3 3 4 4 1 2 1 6 6 6 2 1 3 1 2 6 2 3 2 1 3 3 1 2 2 3 3 5 3 3 2 2 4 3 1 1 2 4 3 5 3 1 2 2 2 3 3 1 2 3 3 0 2 1 3 2 2 3 3 0 2 3 2 2 5 5 2 5 4 7 3 1 2 2 2 2 4 5 3 3 2 3 4 2 3 4 2 2 1 3 3 3 3 2 1 2 5 2 2 2 3 2 3 1 2 5 2 2 4 1 0 2 2 2 2 2 3 1 3 0 1 4 4 3 0 3 2 1 1 2 2 1 1 2 5 3 4 0 1 4 0 2 4 3 3 5 1 4 1 3 2 3 5 4 0 0 3 1 2 2 2 3 2 4 1 4 3 3 2 1 0 6 2 3 1 4 0 2 1 2 2 0 2 4 1 2 3 4 1 3 1 3 1 3 1 1 4 1 3 3 2 3 0 6 3 3 2 5 2 3 4 5 5 2 3 4 3 2 1 3 2 2 3 1 1 1 2 10 3 6 3 2 6 4 4 4 2 2 2 6 2 2 2 2 3 1 3 4 2 1 1 2 5 2 3 3 0 2 5 3 1 4 1 4 3 3 1 3 3 3 5 2 3 4 1 3 1 4 0 4 3 1 2 3 7 1 3 2 3 6 7 5 1 2 1 7 4 4 2 2 5 6 2 2 5 3 3 2 3 3 5 4 3 3 2 5 3 2 8 4 3 5 5 4 2 7 3 3 8 4 3 4 2 5 9 6 7 5 10 6 9 7 6 4 13 6 7 7 9 15 5 12 13 12 13 11 17 19 32 29 22 34 26 34 51 57 68 68 88 92 77 81 64 66 68 49 41 36 30 30 18 30 20 13 18 19 12 14 23 17 22 25 17 24 34 26 35 34 52 23 49 49 30 38 13 17 19 16 12 5 15 12 14 5 5 4 7 5 3 4 5 6 9 5 9 5 4 5 5 4 6 7 3 8 5 5 3 1 3 6 3 5 3 3 3 3 0 1 4 4 3 5 7 3 2 3 2 4 0 3 1 1 4 0 1 2 3 1 4 2 1 1 3 4 2 5 3 3 3 2 2 3 1 2 4 5 1 3 1 3 1 2 2 1 5 5 4 2 1 4 3 2 4 1 2 4 4 2 2 3 2 1 0 3 3 3 0 3 4 1 3 1 2 2 3 1 0 2 1 0 3 3 0 2 4 5 4 2 2 5 1 1 1 2 2 2 2 3 1 0 1 4 3 5 1 0 3 5 2 1 3 2 2 1 3 1 3 1 4 4 1 5 1 1 2 3 2 1 3 1 3 4 2 0 4 0 2 2 2 4 1 0 3 1 2 1 3 2 6 2 3 3 2 4 1 4 1 3 0 6 3 3 3 4 3 3 3 4 1 2 2 1 2 3 7 2 2 2 2 3 4 1 3 3 3 1 2 1 4 2 3 0 2 3 1 4 2 1 0 2 6 3 4 1 4 2 0 4 2 4 0 6 2 3 2 2 4 3 1 3 2 3 2 1 2 3 4 5 4 1 2 4 4 4 3 5 2 4 4 3 3 3 5 3 0 3 4 2 1 4 2 1 4 2 2 0 3 5 2 1 2 4 1 2 3 2 5 3 4 2 3 6 0 3 5 3 2 1 2 2 3 5 6 1 3 2 5 0 2 3 1 4 2 4 3 1 1 4 2 2 2 3 4 3 0 1 4 5 4 0 3 4 3 1 3 3 3 4 3 1 4 3 2 1 4 1 4 6 3 4 5 2 2 5 4 1 1 6 5 5 4 2 2 4 2 5 3 1 1 2 3 3 2 5 4 4 7 5 3 2 8 6 3 5 3 12 4 12 13 7 10 8 8 6 8 7 14 16 12 23 23 22 26 20 23 39 34 42 55 51 46 45 28 28 18 30 28 25 16 16 9 13 20 10 9 15 12 10 7 9 5 10 12 13 8 11 12 12 18 20 16 9 26 22 28 22 23 26 22 16 18 17 10 14 9 13 11 9 12 6 5 4 5 3 7 6 4 2 4 5 4 2 6 3 6 0 5 2 6 5 2 3 3 3 7 3 6 3 0 3 3 2 6 3 4 7 4 3 1 6 3 4 2 2 1 2 5 3 1 5 6 3 3 5 2 5 2 1 2 5 2 2 5 3 4 4 1 2 5 3 2 1 8 4 6 4 1 2 1 2 1 0 4 1 4 4 6 6 3 4 1 6 7 7 2 2 5 2</intensities>
			</dataPoints>
			<nonAmbientPoints type="Temperature" unit="K">
				<measurementTimes unit="seconds" deltaTime="1">0</measurementTimes>
				<nonAmbientValues>298.000</nonAmbientValues>
			</nonAmbientPoints>
		</scan>
	</xrdMeasurement>
</xrdMeasurements>